Workbook

Sheet ta_hm80L18L1_veg24beta
A1: T_MAPCODE_v24beta | B1: NATURAL_v24beta | C1: NOT_NATURA_v24beta | D1: Nat2018v24beta | E1: Tot2018v24beta | F1: PcNat2018v24beta | G1: NAME | H1: MAPCODE18v18 | I1: RLE2022 | J1: NATURALv18 | K1: NOT_NATURAv18 | L1: Nat2018v18 | M1: Tot2018v18 | N1: pNat2018v18 | O1: diff p nat | P1: comment
A2: AT15 | B2: 14595300 | C2: 18900 | D2: =B2/1000000 -> 14.5953 | E2: =(B2+C2)/1000000 -> 14.6142 | F2: =B2/(B2+C2) -> 0.99870674 | G2: Albany Arid Thicket | H2: AT15 | I2: =VLOOKUP(H2,Sheet2!$A$2:$B$459, 2, FALSE) -> LC | J2: 14593500 | K2: 18900 | L2: 14.5935 | M2: 14.6124 | N2: =L2/M2 -> 0.99870658 | O2: =N2-F2 -> -1.5930805e-07
A3: AT16 | B3: 51284700 | C3: 2475900 | D3: =B3/1000000 -> 51.2847 | E3: =(B3+C3)/1000000 -> 53.7606 | F3: =B3/(B3+C3) -> 0.95394583 | G3: Albany Bontveld | H3: AT16 | I3: =VLOOKUP(H3,Sheet2!$A$2:$B$459, 2, FALSE) -> LC | J3: 51284700 | K3: 2475900 | L3: 51.2847 | M3: 53.7606 | N3: =L3/M3 -> 0.95394583 | O3: =N3-F3 -> 0
A4: AT17 | B4: 579072600 | C4: 150138900 | D4: =B4/1000000 -> 579.0726 | E4: =(B4+C4)/1000000 -> 729.2115 | F4: =B4/(B4+C4) -> 0.79410788 | G4: Albany Mesic Thicket | H4: AT17 | I4: =VLOOKUP(H4,Sheet2!$A$2:$B$459, 2, FALSE) -> LC | J4: 579081600 | K4: 150135300 | L4: 579.0816 | M4: 729.2169 | N4: =L4/M4 -> 0.79411434 | O4: =N4-F4 -> 6.4614759e-06
A5: AT18 | B5: 1038102300 | C5: 137548800 | D5: =B5/1000000 -> 1038.1023 | E5: =(B5+C5)/1000000 -> 1175.6511 | F5: =B5/(B5+C5) -> 0.88300202 | G5: Albany Valley Thicket | H5: AT18 | I5: =VLOOKUP(H5,Sheet2!$A$2:$B$459, 2, FALSE) -> LC | J5: 1038104100 | K5: 137548800 | L5: 1038.1041 | M5: 1175.6529 | N5: =L5/M5 -> 0.8830022 | O5: =N5-F5 -> 1.7913141e-07
A6: AT19 | B6: 1062972000 | C6: 14873400 | D6: =B6/1000000 -> 1062.972 | E6: =(B6+C6)/1000000 -> 1077.8454 | F6: =B6/(B6+C6) -> 0.9862008 | G6: Baviaans Valley Thicket | H6: AT19 | I6: =VLOOKUP(H6,Sheet2!$A$2:$B$459, 2, FALSE) -> LC | J6: 1062635400 | K6: 14873400 | L6: 1062.6354 | M6: 1077.5088 | N6: =L6/M6 -> 0.98619649 | O6: =N6-F6 -> -4.3106928e-06
A7: AT20 | B7: 20179800 | C7: 15348600 | D7: =B7/1000000 -> 20.1798 | E7: =(B7+C7)/1000000 -> 35.5284 | F7: =B7/(B7+C7) -> 0.56799068 | G7: Bethelsdorp Bontveld | H7: AT20 | I7: =VLOOKUP(H7,Sheet2!$A$2:$B$459, 2, FALSE) -> LC | J7: 20180700 | K7: 15348600 | L7: 20.1807 | M7: 35.5293 | N7: =L7/M7 -> 0.56800162 | O7: =N7-F7 -> 1.0943317e-05
A8: AT21 | B8: 312208200 | C8: 74132100 | D8: =B8/1000000 -> 312.2082 | E8: =(B8+C8)/1000000 -> 386.3403 | F8: =B8/(B8+C8) -> 0.80811709 | G8: Buffels Mesic Thicket | H8: AT21 | I8: =VLOOKUP(H8,Sheet2!$A$2:$B$459, 2, FALSE) -> LC | J8: 312210900 | K8: 74131200 | L8: 312.2109 | M8: 386.3421 | N8: =L8/M8 -> 0.80812032 | O8: =N8-F8 -> 3.2235401e-06
A9: AT22 | B9: 94256100 | C9: 121205700 | D9: =B9/1000000 -> 94.2561 | E9: =(B9+C9)/1000000 -> 215.4618 | F9: =B9/(B9+C9) -> 0.43746084 | G9: Buffels Valley Thicket | H9: AT22 | I9: =VLOOKUP(H9,Sheet2!$A$2:$B$459, 2, FALSE) -> CR | J9: 94257000 | K9: 121207500 | L9: 94.257 | M9: 215.4645 | N9: =L9/M9 -> 0.43745954 | O9: =N9-F9 -> -1.3048287e-06
A10: AT23 | B10: 269073900 | C10: 42062400 | D10: =B10/1000000 -> 269.0739 | E10: =(B10+C10)/1000000 -> 311.1363 | F10: =B10/(B10+C10) -> 0.86481037 | G10: Crossroads Grassland Thicket | H10: AT23 | I10: =VLOOKUP(H10,Sheet2!$A$2:$B$459, 2, FALSE) -> LC | J10: 269076600 | K10: 42062400 | L10: 269.0766 | M10: 311.139 | N10: =L10/M10 -> 0.86481155 | O10: =N10-F10 -> 1.1731477e-06
A11: AT24 | B11: 2605178700 | C11: 370825200 | D11: =B11/1000000 -> 2605.1787 | E11: =(B11+C11)/1000000 -> 2976.0039 | F11: =B11/(B11+C11) -> 0.87539492 | G11: Doubledrift Karroid Thicket | H11: AT24 | I11: =VLOOKUP(H11,Sheet2!$A$2:$B$459, 2, FALSE) -> LC | J11: 2605095000 | K11: 370824300 | L11: 2605.095 | M11: 2975.9193 | N11: =L11/M11 -> 0.87539168 | O11: =N11-F11 -> -3.2398693e-06
A12: AT25 | B12: 2113814700 | C12: 15148800 | D12: =B12/1000000 -> 2113.8147 | E12: =(B12+C12)/1000000 -> 2128.9635 | F12: =B12/(B12+C12) -> 0.99288442 | G12: Eastern Gwarrieveld | H12: AT25 | I12: =VLOOKUP(H12,Sheet2!$A$2:$B$459, 2, FALSE) -> LC | J12: 2113818300 | K12: 15148800 | L12: 2113.8183 | M12: 2128.9671 | N12: =L12/M12 -> 0.99288444 | O12: =N12-F12 -> 1.2032159e-08
A13: AT26 | B13: 30345300 | C13: 10122300 | D13: =B13/1000000 -> 30.3453 | E13: =(B13+C13)/1000000 -> 40.4676 | F13: =B13/(B13+C13) -> 0.74986656 | G13: Elands Forest Thicket | H13: AT26 | I13: =VLOOKUP(H13,Sheet2!$A$2:$B$459, 2, FALSE) -> LC | J13: 30347100 | K13: 10121400 | L13: 30.3471 | M13: 40.4685 | N13: =L13/M13 -> 0.74989436 | O13: =N13-F13 -> 2.7802367e-05
... A22: AT35 | B22: 18552600 | C22: 11601900 | D22: =B22/1000000 -> 18.5526 | E22: =(B22+C22)/1000000 -> 30.1545 | F22: =B22/(B22+C22) -> 0.61525146 | G22: Geluk Grassland Thicket | H22: AT35 | I22: =VLOOKUP(H22,Sheet2!$A$2:$B$459, 2, FALSE) -> LC | J22: 18552600 | K22: 11601900 | L22: 18.5526 | M22: 30.1545 | N22: =L22/M22 -> 0.61525146 | O22: =N22-F22 -> 0
A23: AT36 | B23: 30100500 | C23: 21305700 | D23: =B23/1000000 -> 30.1005 | E23: =(B23+C23)/1000000 -> 51.4062 | F23: =B23/(B23+C23) -> 0.58554221 | G23: Goukamma Dune Thicket | H23: AT36 | I23: =VLOOKUP(H23,Sheet2!$A$2:$B$459, 2, FALSE) -> LC | J23: 64710900 | K23: 27067500 | L23: 64.7109 | M23: 91.7784 | N23: =L23/M23 -> 0.70507767 | O23: =N23-F23 -> 0.11953545 | P23: decrease in size of type, drop in % nat
A24: AT37 | B24: 107244900 | C24: 69426900 | D24: =B24/1000000 -> 107.2449 | E24: =(B24+C24)/1000000 -> 176.6718 | F24: =B24/(B24+C24) -> 0.60702897 | G24: Gouritz Valley Thicket | H24: AT37 | I24: =VLOOKUP(H24,Sheet2!$A$2:$B$459, 2, FALSE) -> CR | J24: 107375400 | K24: 69479100 | L24: 107.3754 | M24: 176.8545 | N24: =L24/M24 -> 0.60713977 | O24: =N24-F24 -> 0.00011080186
A25: AT38 | B25: 857895300 | C25: 432946800 | D25: =B25/1000000 -> 857.8953 | E25: =(B25+C25)/1000000 -> 1290.8421 | F25: =B25/(B25+C25) -> 0.66460127 | G25: Grahamstown Grassland Thicket | H25: AT38 | I25: =VLOOKUP(H25,Sheet2!$A$2:$B$459, 2, FALSE) -> LC | J25: 857892600 | K25: 432952200 | L25: 857.8926 | M25: 1290.8448 | N25: =L25/M25 -> 0.66459779 | O25: =N25-F25 -> -3.481769e-06
A26: AT39 | B26: 220023900 | C26: 25822800 | D26: =B26/1000000 -> 220.0239 | E26: =(B26+C26)/1000000 -> 245.8467 | F26: =B26/(B26+C26) -> 0.89496381 | G26: Grassridge Bontveld | H26: AT39 | I26: =VLOOKUP(H26,Sheet2!$A$2:$B$459, 2, FALSE) -> LC | J26: 220021200 | K26: 25821900 | L26: 220.0212 | M26: 245.8431 | N26: =L26/M26 -> 0.89496594 | O26: =N26-F26 -> 2.1227756e-06
A27: AT40 | B27: 467093700 | C27: 129210300 | D27: =B27/1000000 -> 467.0937 | E27: =(B27+C27)/1000000 -> 596.304 | F27: =B27/(B27+C27) -> 0.78331472 | G27: Hartenbos Dune Thicket | H27: AT40 | I27: =VLOOKUP(H27,Sheet2!$A$2:$B$459, 2, FALSE) -> EN | J27: 516087900 | K27: 134748900 | L27: 516.0879 | M27: 650.8368 | N27: =L27/M27 -> 0.79296054 | O27: =N27-F27 -> 0.0096458207
A28: AT41 | B28: 209875500 | C28: 97653600 | D28: =B28/1000000 -> 209.8755 | E28: =(B28+C28)/1000000 -> 307.5291 | F28: =B28/(B28+C28) -> 0.68245737 | G28: Kasouga Dune Thicket | H28: AT41 | I28: =VLOOKUP(H28,Sheet2!$A$2:$B$459, 2, FALSE) -> LC | J28: 209864700 | K28: 97654500 | L28: 209.8647 | M28: 307.5192 | N28: =L28/M28 -> 0.68244422 | O28: =N28-F28 -> -1.3149332e-05
A29: AT42 | B29: 53350200 | C29: 6502500 | D29: =B29/1000000 -> 53.3502 | E29: =(B29+C29)/1000000 -> 59.8527 | F29: =B29/(B29+C29) -> 0.89135828 | G29: Koedoeskloof Karroid Thicket | H29: AT42 | I29: =VLOOKUP(H29,Sheet2!$A$2:$B$459, 2, FALSE) -> LC | J29: 53350200 | K29: 6502500 | L29: 53.3502 | M29: 59.8527 | N29: =L29/M29 -> 0.89135828 | O29: =N29-F29 -> 0
A30: AT43 | B30: 266858100 | C30: 19333800 | D30: =B30/1000000 -> 266.8581 | E30: =(B30+C30)/1000000 -> 286.1919 | F30: =B30/(B30+C30) -> 0.93244463 | G30: Mons Ruber Fynbos Thicket | H30: AT43 | I30: =VLOOKUP(H30,Sheet2!$A$2:$B$459, 2, FALSE) -> LC | J30: 266859900 | K30: 19334700 | L30: 266.8599 | M30: 286.1946 | N30: =L30/M30 -> 0.93244212 | O30: =N30-F30 -> -2.5073866e-06
A31: AT44 | B31: 65959200 | C31: 97473600 | D31: =B31/1000000 -> 65.9592 | E31: =(B31+C31)/1000000 -> 163.4328 | F31: =B31/(B31+C31) -> 0.40358606 | G31: Motherwell Karroid Thicket | H31: AT44 | I31: =VLOOKUP(H31,Sheet2!$A$2:$B$459, 2, FALSE) -> CR | J31: 65957400 | K31: 97456500 | L31: 65.9574 | M31: 163.4139 | N31: =L31/M31 -> 0.40362172 | O31: =N31-F31 -> 3.5662673e-05
A32: AT45 | B32: 433495800 | C32: 263493900 | D32: =B32/1000000 -> 433.4958 | E32: =(B32+C32)/1000000 -> 696.9897 | F32: =B32/(B32+C32) -> 0.62195438 | G32: Nanaga Savanna Thicket | H32: AT45 | I32: =VLOOKUP(H32,Sheet2!$A$2:$B$459, 2, FALSE) -> LC | J32: 433501200 | K32: 263493900 | L32: 433.5012 | M32: 696.9951 | N32: =L32/M32 -> 0.62195731 | O32: =N32-F32 -> 2.9289249e-06
A33: AT46 | B33: 553819500 | C33: 18111600 | D33: =B33/1000000 -> 553.8195 | E33: =(B33+C33)/1000000 -> 571.9311 | F33: =B33/(B33+C33) -> 0.96833255 | G33: Oudtshoorn Karroid Thicket | H33: AT46 | I33: =VLOOKUP(H33,Sheet2!$A$2:$B$459, 2, FALSE) -> LC | J33: 553815900 | K33: 18110700 | L33: 553.8159 | M33: 571.9266 | N33: =L33/M33 -> 0.96833387 | O33: =N33-F33 -> 1.3244645e-06
A34: AT47 | B34: 890021700 | C34: 20453400 | D34: =B34/1000000 -> 890.0217 | E34: =(B34+C34)/1000000 -> 910.4751 | F34: =B34/(B34+C34) -> 0.97753546 | G34: Saltaire Karroid Thicket | H34: AT47 | I34: =VLOOKUP(H34,Sheet2!$A$2:$B$459, 2, FALSE) -> LC | J34: 890014500 | K34: 20453400 | L34: 890.0145 | M34: 910.4679 | N34: =L34/M34 -> 0.97753529 | O34: =N34-F34 -> -1.7765003e-07
A35: AT48 | B35: 11918700 | C35: 8438400 | D35: =B35/1000000 -> 11.9187 | E35: =(B35+C35)/1000000 -> 20.3571 | F35: =B35/(B35+C35) -> 0.58548123 | G35: Sardinia Forest Thicket | H35: AT48 | I35: =VLOOKUP(H35,Sheet2!$A$2:$B$459, 2, FALSE) -> LC | J35: 16035300 | K35: 9216000 | L35: 16.0353 | M35: 25.2513 | N35: =L35/M35 -> 0.63502869 | O35: =N35-F35 -> 0.049547459 | P35: decrease in size, loss of nat areas
A36: AT49 | B36: 5544078300 | C36: 103105800 | D36: =B36/1000000 -> 5544.0783 | E36: =(B36+C36)/1000000 -> 5647.1841 | F36: =B36/(B36+C36) -> 0.98174209 | G36: Sundays Arid Thicket | H36: AT49 | I36: =VLOOKUP(H36,Sheet2!$A$2:$B$459, 2, FALSE) -> VU | J36: 5544072000 | K36: 103106700 | L36: 5544.072 | M36: 5647.1787 | N36: =L36/M36 -> 0.98174191 | O36: =N36-F36 -> -1.7683038e-07
A37: AT50 | B37: 516919500 | C37: 60629400 | D37: =B37/1000000 -> 516.9195 | E37: =(B37+C37)/1000000 -> 577.5489 | F37: =B37/(B37+C37) -> 0.89502291 | G37: Sundays Mesic Thicket | H37: AT50 | I37: =VLOOKUP(H37,Sheet2!$A$2:$B$459, 2, FALSE) -> LC | J37: 518705100 | K37: 61492500 | L37: 518.7051 | M37: 580.1976 | N37: =L37/M37 -> 0.89401456 | O37: =N37-F37 -> -0.0010083585
A38: AT51 | B38: 1707247800 | C38: 256230900 | D38: =B38/1000000 -> 1707.2478 | E38: =(B38+C38)/1000000 -> 1963.4787 | F38: =B38/(B38+C38) -> 0.86950156 | G38: Sundays Valley Thicket | H38: AT51 | I38: =VLOOKUP(H38,Sheet2!$A$2:$B$459, 2, FALSE) -> LC | J38: 1707255000 | K38: 256227300 | L38: 1707.255 | M38: 1963.4823 | N38: =L38/M38 -> 0.86950364 | O38: =N38-F38 -> 2.0727431e-06
A39: AT52 | B39: 30384000 | C39: 13223700 | D39: =B39/1000000 -> 30.384 | E39: =(B39+C39)/1000000 -> 43.6077 | F39: =B39/(B39+C39) -> 0.69675768 | G39: Thorndale Forest Thicket | H39: AT52 | I39: =VLOOKUP(H39,Sheet2!$A$2:$B$459, 2, FALSE) -> LC | J39: 30383100 | K39: 13223700 | L39: 30.3831 | M39: 43.6068 | N39: =L39/M39 -> 0.69675142 | O39: =N39-F39 -> -6.258613e-06
A40: AT53 | B40: 16866000 | C40: 10226700 | D40: =B40/1000000 -> 16.866 | E40: =(B40+C40)/1000000 -> 27.0927 | F40: =B40/(B40+C40) -> 0.62252932 | G40: Umtiza Forest Thicket | H40: AT53 | I40: =VLOOKUP(H40,Sheet2!$A$2:$B$459, 2, FALSE) -> CR | J40: 16864200 | K40: 10226700 | L40: 16.8642 | M40: 27.0909 | N40: =L40/M40 -> 0.62250424 | O40: =N40-F40 -> -2.5080275e-05
A41: AT54 | B41: 184980600 | C41: 2754900 | D41: =B41/1000000 -> 184.9806 | E41: =(B41+C41)/1000000 -> 187.7355 | F41: =B41/(B41+C41) -> 0.98532563 | G41: Vanstadens Forest Thicket | H41: AT54 | I41: =VLOOKUP(H41,Sheet2!$A$2:$B$459, 2, FALSE) -> LC | J41: 184973400 | K41: 2754900 | L41: 184.9734 | M41: 187.7283 | N41: =L41/M41 -> 0.98532507 | O41: =N41-F41 -> -5.6281049e-07
A42: AT55 | B42: 743775300 | C42: 16578900 | D42: =B42/1000000 -> 743.7753 | E42: =(B42+C42)/1000000 -> 760.3542 | F42: =B42/(B42+C42) -> 0.97819582 | G42: Western Gwarrieveld | H42: AT55 | I42: =VLOOKUP(H42,Sheet2!$A$2:$B$459, 2, FALSE) -> LC | J42: 743779800 | K42: 16578900 | L42: 743.7798 | M42: 760.3587 | N42: =L42/M42 -> 0.97819595 | O42: =N42-F42 -> 1.2904279e-07
A43: AT56 | B43: 471609000 | C43: 230055300 | D43: =B43/1000000 -> 471.609 | E43: =(B43+C43)/1000000 -> 701.6643 | F43: =B43/(B43+C43) -> 0.67212911 | G43: Hamburg Dune Thicket | H43: AT56 | I43: =VLOOKUP(H43,Sheet2!$A$2:$B$459, 2, FALSE) -> LC | J43: 471612600 | K43: 230056200 | L43: 471.6126 | M43: 701.6688 | N43: =L43/M43 -> 0.67212993 | O43: =N43-F43 -> 8.2007211e-07
A44: AT57 | B44: 107123400 | C44: 29941200 | D44: =B44/1000000 -> 107.1234 | E44: =(B44+C44)/1000000 -> 137.0646 | F44: =B44/(B44+C44) -> 0.7815541 | G44: St Francis Dune Thicket | H44: AT57 | I44: =VLOOKUP(H44,Sheet2!$A$2:$B$459, 2, FALSE) -> LC | J44: 223272000 | K44: 41108400 | L44: 223.272 | M44: 264.3804 | N44: =L44/M44 -> 0.84451041 | O44: =N44-F44 -> 0.062956311 | P44: decrease in size loss of nat areas
A45: AT58 | B45: 2226033900 | C45: 26276400 | D45: =B45/1000000 -> 2226.0339 | E45: =(B45+C45)/1000000 -> 2252.3103 | F45: =B45/(B45+C45) -> 0.98833358 | G45: Willowmore Gwarrieveld | H45: AT58 | I45: =VLOOKUP(H45,Sheet2!$A$2:$B$459, 2, FALSE) -> LC | J45: 2226033000 | K45: 26276400 | L45: 2226.033 | M45: 2252.3094 | N45: =L45/M45 -> 0.98833357 | O45: =N45-F45 -> -4.6617836e-09
A46: AZa1 | B46: 18212400 | C46: 460800 | D46: =B46/1000000 -> 18.2124 | E46: =(B46+C46)/1000000 -> 18.6732 | F46: =B46/(B46+C46) -> 0.97532292 | G46: Fynbos Riparian Vegetation | H46: AZa1 | I46: =VLOOKUP(H46,Sheet2!$A$2:$B$459, 2, FALSE) -> LC | J46: 18214200 | K46: 460800 | L46: 18.2142 | M46: 18.675 | N46: =L46/M46 -> 0.9753253 | O46: =N46-F46 -> 2.3785135e-06
A47: AZa2 | B47: 118694700 | C47: 232086600 | D47: =B47/1000000 -> 118.6947 | E47: =(B47+C47)/1000000 -> 350.7813 | F47: =B47/(B47+C47) -> 0.33837237 | G47: Cape Lowland Alluvial Vegetation | H47: AZa2 | I47: =VLOOKUP(H47,Sheet2!$A$2:$B$459, 2, FALSE) -> EN | J47: 118718100 | K47: 232169400 | L47: 118.7181 | M47: 350.8875 | N47: =L47/M47 -> 0.33833665 | O47: =N47-F47 -> -3.5724116e-05
A48: AZa3 | B48: 546156000 | C48: 321687000 | D48: =B48/1000000 -> 546.156 | E48: =(B48+C48)/1000000 -> 867.843 | F48: =B48/(B48+C48) -> 0.62932581 | G48: Lower Gariep Alluvial Vegetation | H48: AZa3 | I48: =VLOOKUP(H48,Sheet2!$A$2:$B$459, 2, FALSE) -> LC | J48: 546154200 | K48: 321687000 | L48: 546.1542 | M48: 867.8412 | N48: =L48/M48 -> 0.62932504 | O48: =N48-F48 -> -7.6881985e-07
...

Sheet Sheet1
C1: nat m2 | D1: notnat m2 | E1: nat km2 | F1: tot km2 | G1: %nat
A2: Western Highveld Sandy Grassland | B2: Gh14 | C2: 1522672200 | D2: 7069559400 | E2: 1522.6722 | F2: 8592.2316 | G2: 0.17721499
A3: Carletonville Dolomite Grassland | B3: Gh15 | C3: 5651321400 | D3: 3549127500 | E3: 5651.3214 | F3: 9200.4489 | G3: 0.61424409
A4: Western Highveld Sandy Grassland | B4: Gh14 | C4: 3758412600 | D4: 5429025000 | E4: 3758.4126 | F4: 9187.4376 | G4: 0.4090817
A5: Carletonville Dolomite Grassland | B5: Gh15 | C5: 5545276200 | D5: 3053112300 | E5: 5545.2762 | F5: 8598.3885 | G5: 0.64492041

Sheet Sheet2
A1: MAPCODE18 | B1: RLE2021May
A2: AT15 | B2: LC
A3: AT16 | B3: LC
A4: AT17 | B4: LC
A5: AT18 | B5: LC
A6: AT19 | B6: LC
A7: AT20 | B7: LC
A8: AT21 | B8: LC
A9: AT22 | B9: CR
A10: AT23 | B10: LC
A11: AT24 | B11: LC
A12: AT25 | B12: LC
... A459: SVs8 | B459: LC
